============================= test session starts ==============================
platform linux -- Python 3.9.2, pytest-6.2.2, py-1.10.0, pluggy-0.13.1
rootdir: /home/stidsem4/iut/2021/controle/mathis.verla/c16_03
collected 7 items

test_16_03.py F.FFFFF                                                    [100%]

=================================== FAILURES ===================================
_____________________________ Test1603sute.test_10 _____________________________

self = <c16_03.test_16_03.Test1603sute testMethod=test_10>

    def test_10(self):
        try:
>           from .main  import Note
E             File "/home/stidsem4/iut/2021/controle/mathis.verla/c16_03/main.py", line 40
E               if x[0]='eleve1' and x[1]='math':
E               ^
E           IndentationError: expected an indented block

test_16_03.py:94: IndentationError

During handling of the above exception, another exception occurred:

self = <c16_03.test_16_03.Test1603sute testMethod=test_10>

    def test_10(self):
        try:
            from .main  import Note
        except:
>          assert False
E          AssertionError: assert False

test_16_03.py:96: AssertionError
_____________________________ Test1603sute.test_4 ______________________________

self = <c16_03.test_16_03.Test1603sute testMethod=test_4>

    def test_4(self):
        try:
>           from main import moyenne_tuples
E           ImportError: cannot import name 'moyenne_tuples' from 'main' (/home/stidsem4/iut/2021/controle/mathis.verla/main.py)

test_16_03.py:16: ImportError

During handling of the above exception, another exception occurred:

self = <c16_03.test_16_03.Test1603sute testMethod=test_4>

    def test_4(self):
        try:
            from main import moyenne_tuples
        except ImportError:
            try:
>               from .main import moyenne_tuple as moyenne_tuples
E                 File "/home/stidsem4/iut/2021/controle/mathis.verla/c16_03/main.py", line 40
E                   if x[0]='eleve1' and x[1]='math':
E                   ^
E               IndentationError: expected an indented block

test_16_03.py:19: IndentationError
_____________________________ Test1603sute.test_5 ______________________________

self = <c16_03.test_16_03.Test1603sute testMethod=test_5>

    def test_5(self):
        try:
>           from .main  import Note, onotes
E             File "/home/stidsem4/iut/2021/controle/mathis.verla/c16_03/main.py", line 40
E               if x[0]='eleve1' and x[1]='math':
E               ^
E           IndentationError: expected an indented block

test_16_03.py:33: IndentationError

During handling of the above exception, another exception occurred:

self = <c16_03.test_16_03.Test1603sute testMethod=test_5>

    def test_5(self):
        try:
            from .main  import Note, onotes
        except:
>           assert False
E           AssertionError: assert False

test_16_03.py:35: AssertionError
_____________________________ Test1603sute.test_6 ______________________________

self = <c16_03.test_16_03.Test1603sute testMethod=test_6>

    def test_6(self):
>       from .main import Note, onotes
E         File "/home/stidsem4/iut/2021/controle/mathis.verla/c16_03/main.py", line 40
E           if x[0]='eleve1' and x[1]='math':
E           ^
E       IndentationError: expected an indented block

test_16_03.py:41: IndentationError
_____________________________ Test1603sute.test_8 ______________________________

self = <c16_03.test_16_03.Test1603sute testMethod=test_8>

    def test_8(self):
        try:
>           from .main import Note
E             File "/home/stidsem4/iut/2021/controle/mathis.verla/c16_03/main.py", line 40
E               if x[0]='eleve1' and x[1]='math':
E               ^
E           IndentationError: expected an indented block

test_16_03.py:67: IndentationError
_____________________________ Test1603sute.test_9 ______________________________

self = <c16_03.test_16_03.Test1603sute testMethod=test_9>

    def test_9(self):
        try:
>           from .main  import Note
E             File "/home/stidsem4/iut/2021/controle/mathis.verla/c16_03/main.py", line 40
E               if x[0]='eleve1' and x[1]='math':
E               ^
E           IndentationError: expected an indented block

test_16_03.py:87: IndentationError

During handling of the above exception, another exception occurred:

self = <c16_03.test_16_03.Test1603sute testMethod=test_9>

    def test_9(self):
        try:
            from .main  import Note
        except:
>          assert False
E          AssertionError: assert False

test_16_03.py:89: AssertionError
=========================== short test summary info ============================
FAILED test_16_03.py::Test1603sute::test_10 - AssertionError: assert False
FAILED test_16_03.py::Test1603sute::test_4 -   File "/home/stidsem4/iut/2021/...
FAILED test_16_03.py::Test1603sute::test_5 - AssertionError: assert False
FAILED test_16_03.py::Test1603sute::test_6 -   File "/home/stidsem4/iut/2021/...
FAILED test_16_03.py::Test1603sute::test_8 -   File "/home/stidsem4/iut/2021/...
FAILED test_16_03.py::Test1603sute::test_9 - AssertionError: assert False
========================= 6 failed, 1 passed in 0.07s ==========================
